2019-11-05 11:19:40 _internal.py[line:122] INFO  * Running on http://0.0.0.0:5000/ (Press CTRL+C to quit)
2019-11-05 11:21:14 _internal.py[line:122] INFO  * Running on http://0.0.0.0:5000/ (Press CTRL+C to quit)
2019-11-05 11:21:40 _internal.py[line:122] INFO  * Running on http://0.0.0.0:5000/ (Press CTRL+C to quit)
2019-11-05 11:36:54 _internal.py[line:122] INFO  * Running on http://0.0.0.0:5000/ (Press CTRL+C to quit)
2019-11-05 11:37:21 _internal.py[line:122] INFO 127.0.0.1 - - [05/Nov/2019 11:37:21] "GET /newrank/count HTTP/1.1" 200 -
2019-11-05 11:37:28 _internal.py[line:122] INFO 127.0.0.1 - - [05/Nov/2019 11:37:28] "GET /newrank/random HTTP/1.1" 200 -
2019-11-05 15:06:42 _internal.py[line:122] INFO  * Running on http://0.0.0.0:5000/ (Press CTRL+C to quit)
2019-11-05 16:13:20 _internal.py[line:122] INFO  * Running on http://0.0.0.0:5000/ (Press CTRL+C to quit)
2019-11-05 16:25:34 _internal.py[line:122] INFO  * Running on http://0.0.0.0:5000/ (Press CTRL+C to quit)
2019-11-05 16:26:09 _internal.py[line:122] INFO 127.0.0.1 - - [05/Nov/2019 16:26:09] "GET / HTTP/1.1" 200 -
2019-11-05 16:26:39 app.py[line:1891] ERROR Exception on /newrank/count [GET]
Traceback (most recent call last):
  File "C:\Users\Administrator\AppData\Local\Programs\Python\Python36\lib\site-packages\redis\connection.py", line 518, in connect
    sock = self._connect()
  File "C:\Users\Administrator\AppData\Local\Programs\Python\Python36\lib\site-packages\redis\connection.py", line 575, in _connect
    raise err
  File "C:\Users\Administrator\AppData\Local\Programs\Python\Python36\lib\site-packages\redis\connection.py", line 563, in _connect
    sock.connect(socket_address)
TimeoutError: [WinError 10060] 由于连接方在一段时间后没有正确答复或连接的主机没有反应，连接尝试失败。

During handling of the above exception, another exception occurred:

Traceback (most recent call last):
  File "C:\Users\Administrator\AppData\Local\Programs\Python\Python36\lib\site-packages\flask\app.py", line 2446, in wsgi_app
    response = self.full_dispatch_request()
  File "C:\Users\Administrator\AppData\Local\Programs\Python\Python36\lib\site-packages\flask\app.py", line 1951, in full_dispatch_request
    rv = self.handle_user_exception(e)
  File "C:\Users\Administrator\AppData\Local\Programs\Python\Python36\lib\site-packages\flask\app.py", line 1820, in handle_user_exception
    reraise(exc_type, exc_value, tb)
  File "C:\Users\Administrator\AppData\Local\Programs\Python\Python36\lib\site-packages\flask\_compat.py", line 39, in reraise
    raise value
  File "C:\Users\Administrator\AppData\Local\Programs\Python\Python36\lib\site-packages\flask\app.py", line 1949, in full_dispatch_request
    rv = self.dispatch_request()
  File "C:\Users\Administrator\AppData\Local\Programs\Python\Python36\lib\site-packages\flask\app.py", line 1935, in dispatch_request
    return self.view_functions[rule.endpoint](**req.view_args)
  File "C:\Users\Administrator\Desktop\CookiesPool-master\cookiespool\api.py", line 78, in count
    count = getattr(g, website + '_cookies').count()
  File "C:\Users\Administrator\Desktop\CookiesPool-master\cookiespool\db.py", line 55, in count
    return self.db.hlen(self.name())
  File "C:\Users\Administrator\AppData\Local\Programs\Python\Python36\lib\site-packages\redis\client.py", line 2735, in hlen
    return self.execute_command('HLEN', name)
  File "C:\Users\Administrator\AppData\Local\Programs\Python\Python36\lib\site-packages\redis\client.py", line 836, in execute_command
    conn = self.connection or pool.get_connection(command_name, **options)
  File "C:\Users\Administrator\AppData\Local\Programs\Python\Python36\lib\site-packages\redis\connection.py", line 1051, in get_connection
    connection.connect()
  File "C:\Users\Administrator\AppData\Local\Programs\Python\Python36\lib\site-packages\redis\connection.py", line 523, in connect
    raise ConnectionError(self._error_message(e))
redis.exceptions.ConnectionError: Error 10060 connecting to 192.169.1.1:6379. 由于连接方在一段时间后没有正确答复或连接的主机没有反应，连接尝试失败。.
2019-11-05 16:26:39 _internal.py[line:122] INFO 127.0.0.1 - - [05/Nov/2019 16:26:39] "GET /newrank/count HTTP/1.1" 500 -
2019-11-05 17:47:46 _internal.py[line:122] INFO  * Running on http://0.0.0.0:6000/ (Press CTRL+C to quit)
2019-11-05 18:01:03 _internal.py[line:122] INFO  * Running on http://0.0.0.0:6000/ (Press CTRL+C to quit)
2019-11-05 18:02:16 _internal.py[line:122] INFO  * Running on http://127.0.0.1:6000/ (Press CTRL+C to quit)
2019-11-05 18:15:49 _internal.py[line:122] INFO  * Running on http://127.0.0.1:6000/ (Press CTRL+C to quit)
2019-11-05 18:17:56 _internal.py[line:122] INFO  * Running on http://127.0.0.1:6000/ (Press CTRL+C to quit)
2019-11-05 18:18:12 _internal.py[line:122] INFO  * Running on http://127.0.0.1:5000/ (Press CTRL+C to quit)
2019-11-05 18:18:17 _internal.py[line:122] INFO 127.0.0.1 - - [05/Nov/2019 18:18:17] "GET / HTTP/1.1" 200 -
2019-11-05 18:18:34 _internal.py[line:122] INFO 127.0.0.1 - - [05/Nov/2019 18:18:34] "GET /newrank/count HTTP/1.1" 200 -
2019-11-05 18:18:39 _internal.py[line:122] INFO 127.0.0.1 - - [05/Nov/2019 18:18:39] "GET /newrank/count HTTP/1.1" 200 -
2019-11-05 18:18:41 _internal.py[line:122] INFO 127.0.0.1 - - [05/Nov/2019 18:18:41] "GET /newrank/count HTTP/1.1" 200 -
2019-11-05 18:21:01 _internal.py[line:122] INFO  * Running on http://127.0.0.1:5000/ (Press CTRL+C to quit)
2019-11-05 18:21:04 _internal.py[line:122] INFO 127.0.0.1 - - [05/Nov/2019 18:21:04] "GET /newrank/count HTTP/1.1" 200 -
2019-11-05 18:21:04 _internal.py[line:122] INFO 127.0.0.1 - - [05/Nov/2019 18:21:04] "GET /newrank/count HTTP/1.1" 200 -
2019-11-06 09:23:37 app.py[line:1891] ERROR Exception on /newrank/random [GET]
Traceback (most recent call last):
  File "C:\Users\Administrator\AppData\Local\Programs\Python\Python36\lib\site-packages\redis\connection.py", line 518, in connect
    sock = self._connect()
  File "C:\Users\Administrator\AppData\Local\Programs\Python\Python36\lib\site-packages\redis\connection.py", line 575, in _connect
    raise err
  File "C:\Users\Administrator\AppData\Local\Programs\Python\Python36\lib\site-packages\redis\connection.py", line 563, in _connect
    sock.connect(socket_address)
TimeoutError: [WinError 10060] 由于连接方在一段时间后没有正确答复或连接的主机没有反应，连接尝试失败。

During handling of the above exception, another exception occurred:

Traceback (most recent call last):
  File "C:\Users\Administrator\AppData\Local\Programs\Python\Python36\lib\site-packages\flask\app.py", line 2446, in wsgi_app
    response = self.full_dispatch_request()
  File "C:\Users\Administrator\AppData\Local\Programs\Python\Python36\lib\site-packages\flask\app.py", line 1951, in full_dispatch_request
    rv = self.handle_user_exception(e)
  File "C:\Users\Administrator\AppData\Local\Programs\Python\Python36\lib\site-packages\flask\app.py", line 1820, in handle_user_exception
    reraise(exc_type, exc_value, tb)
  File "C:\Users\Administrator\AppData\Local\Programs\Python\Python36\lib\site-packages\flask\_compat.py", line 39, in reraise
    raise value
  File "C:\Users\Administrator\AppData\Local\Programs\Python\Python36\lib\site-packages\flask\app.py", line 1949, in full_dispatch_request
    rv = self.dispatch_request()
  File "C:\Users\Administrator\AppData\Local\Programs\Python\Python36\lib\site-packages\flask\app.py", line 1935, in dispatch_request
    return self.view_functions[rule.endpoint](**req.view_args)
  File "c:\Users\Administrator\Desktop\CookiesPool-master\cookiespool\api.py", line 47, in random
    usernames = getattr(g, website + '_cookies').usernames()  # 取出所有key值
  File "c:\Users\Administrator\Desktop\CookiesPool-master\cookiespool\db.py", line 69, in usernames
    return self.db.hkeys(self.name())
  File "C:\Users\Administrator\AppData\Local\Programs\Python\Python36\lib\site-packages\redis\client.py", line 2731, in hkeys
    return self.execute_command('HKEYS', name)
  File "C:\Users\Administrator\AppData\Local\Programs\Python\Python36\lib\site-packages\redis\client.py", line 836, in execute_command
    conn = self.connection or pool.get_connection(command_name, **options)
  File "C:\Users\Administrator\AppData\Local\Programs\Python\Python36\lib\site-packages\redis\connection.py", line 1051, in get_connection
    connection.connect()
  File "C:\Users\Administrator\AppData\Local\Programs\Python\Python36\lib\site-packages\redis\connection.py", line 523, in connect
    raise ConnectionError(self._error_message(e))
redis.exceptions.ConnectionError: Error 10060 connecting to 47.106.107.0:6379. 由于连接方在一段时间后没有正确答复或连接的主机没有反应，连接尝试失败。.
2019-11-06 09:23:37 _internal.py[line:122] INFO 127.0.0.1 - - [06/Nov/2019 09:23:37] "GET /newrank/random HTTP/1.1" 500 -
2019-11-06 09:24:00 app.py[line:1891] ERROR Exception on /newrank/random [GET]
Traceback (most recent call last):
  File "C:\Users\Administrator\AppData\Local\Programs\Python\Python36\lib\site-packages\redis\connection.py", line 518, in connect
    sock = self._connect()
  File "C:\Users\Administrator\AppData\Local\Programs\Python\Python36\lib\site-packages\redis\connection.py", line 575, in _connect
    raise err
  File "C:\Users\Administrator\AppData\Local\Programs\Python\Python36\lib\site-packages\redis\connection.py", line 563, in _connect
    sock.connect(socket_address)
TimeoutError: [WinError 10060] 由于连接方在一段时间后没有正确答复或连接的主机没有反应，连接尝试失败。

During handling of the above exception, another exception occurred:

Traceback (most recent call last):
  File "C:\Users\Administrator\AppData\Local\Programs\Python\Python36\lib\site-packages\flask\app.py", line 2446, in wsgi_app
    response = self.full_dispatch_request()
  File "C:\Users\Administrator\AppData\Local\Programs\Python\Python36\lib\site-packages\flask\app.py", line 1951, in full_dispatch_request
    rv = self.handle_user_exception(e)
  File "C:\Users\Administrator\AppData\Local\Programs\Python\Python36\lib\site-packages\flask\app.py", line 1820, in handle_user_exception
    reraise(exc_type, exc_value, tb)
  File "C:\Users\Administrator\AppData\Local\Programs\Python\Python36\lib\site-packages\flask\_compat.py", line 39, in reraise
    raise value
  File "C:\Users\Administrator\AppData\Local\Programs\Python\Python36\lib\site-packages\flask\app.py", line 1949, in full_dispatch_request
    rv = self.dispatch_request()
  File "C:\Users\Administrator\AppData\Local\Programs\Python\Python36\lib\site-packages\flask\app.py", line 1935, in dispatch_request
    return self.view_functions[rule.endpoint](**req.view_args)
  File "c:\Users\Administrator\Desktop\CookiesPool-master\cookiespool\api.py", line 47, in random
    usernames = getattr(g, website + '_cookies').usernames()  # 取出所有key值
  File "c:\Users\Administrator\Desktop\CookiesPool-master\cookiespool\db.py", line 69, in usernames
    return self.db.hkeys(self.name())
  File "C:\Users\Administrator\AppData\Local\Programs\Python\Python36\lib\site-packages\redis\client.py", line 2731, in hkeys
    return self.execute_command('HKEYS', name)
  File "C:\Users\Administrator\AppData\Local\Programs\Python\Python36\lib\site-packages\redis\client.py", line 836, in execute_command
    conn = self.connection or pool.get_connection(command_name, **options)
  File "C:\Users\Administrator\AppData\Local\Programs\Python\Python36\lib\site-packages\redis\connection.py", line 1051, in get_connection
    connection.connect()
  File "C:\Users\Administrator\AppData\Local\Programs\Python\Python36\lib\site-packages\redis\connection.py", line 523, in connect
    raise ConnectionError(self._error_message(e))
redis.exceptions.ConnectionError: Error 10060 connecting to 47.106.107.0:6379. 由于连接方在一段时间后没有正确答复或连接的主机没有反应，连接尝试失败。.
2019-11-06 09:24:00 _internal.py[line:122] INFO 127.0.0.1 - - [06/Nov/2019 09:24:00] "GET /newrank/random HTTP/1.1" 500 -
2019-11-06 09:24:13 _internal.py[line:122] INFO  * Running on http://0.0.0.0:5000/ (Press CTRL+C to quit)
2019-11-06 09:24:36 app.py[line:1891] ERROR Exception on /newrank/random [GET]
Traceback (most recent call last):
  File "C:\Users\Administrator\AppData\Local\Programs\Python\Python36\lib\site-packages\redis\connection.py", line 518, in connect
    sock = self._connect()
  File "C:\Users\Administrator\AppData\Local\Programs\Python\Python36\lib\site-packages\redis\connection.py", line 575, in _connect
    raise err
  File "C:\Users\Administrator\AppData\Local\Programs\Python\Python36\lib\site-packages\redis\connection.py", line 563, in _connect
    sock.connect(socket_address)
TimeoutError: [WinError 10060] 由于连接方在一段时间后没有正确答复或连接的主机没有反应，连接尝试失败。

During handling of the above exception, another exception occurred:

Traceback (most recent call last):
  File "C:\Users\Administrator\AppData\Local\Programs\Python\Python36\lib\site-packages\flask\app.py", line 2446, in wsgi_app
    response = self.full_dispatch_request()
  File "C:\Users\Administrator\AppData\Local\Programs\Python\Python36\lib\site-packages\flask\app.py", line 1951, in full_dispatch_request
    rv = self.handle_user_exception(e)
  File "C:\Users\Administrator\AppData\Local\Programs\Python\Python36\lib\site-packages\flask\app.py", line 1820, in handle_user_exception
    reraise(exc_type, exc_value, tb)
  File "C:\Users\Administrator\AppData\Local\Programs\Python\Python36\lib\site-packages\flask\_compat.py", line 39, in reraise
    raise value
  File "C:\Users\Administrator\AppData\Local\Programs\Python\Python36\lib\site-packages\flask\app.py", line 1949, in full_dispatch_request
    rv = self.dispatch_request()
  File "C:\Users\Administrator\AppData\Local\Programs\Python\Python36\lib\site-packages\flask\app.py", line 1935, in dispatch_request
    return self.view_functions[rule.endpoint](**req.view_args)
  File "c:\Users\Administrator\Desktop\CookiesPool-master\cookiespool\api.py", line 47, in random
    usernames = getattr(g, website + '_cookies').usernames()  # 取出所有key值
  File "c:\Users\Administrator\Desktop\CookiesPool-master\cookiespool\db.py", line 69, in usernames
    return self.db.hkeys(self.name())
  File "C:\Users\Administrator\AppData\Local\Programs\Python\Python36\lib\site-packages\redis\client.py", line 2731, in hkeys
    return self.execute_command('HKEYS', name)
  File "C:\Users\Administrator\AppData\Local\Programs\Python\Python36\lib\site-packages\redis\client.py", line 836, in execute_command
    conn = self.connection or pool.get_connection(command_name, **options)
  File "C:\Users\Administrator\AppData\Local\Programs\Python\Python36\lib\site-packages\redis\connection.py", line 1051, in get_connection
    connection.connect()
  File "C:\Users\Administrator\AppData\Local\Programs\Python\Python36\lib\site-packages\redis\connection.py", line 523, in connect
    raise ConnectionError(self._error_message(e))
redis.exceptions.ConnectionError: Error 10060 connecting to 47.106.107.0:6379. 由于连接方在一段时间后没有正确答复或连接的主机没有反应，连接尝试失败。.
2019-11-06 09:24:36 _internal.py[line:122] INFO 127.0.0.1 - - [06/Nov/2019 09:24:36] "GET /newrank/random HTTP/1.1" 500 -
2019-11-06 09:24:47 _internal.py[line:122] INFO 127.0.0.1 - - [06/Nov/2019 09:24:47] "GET / HTTP/1.1" 200 -
2019-11-06 09:25:20 app.py[line:1891] ERROR Exception on /newrank/count [GET]
Traceback (most recent call last):
  File "C:\Users\Administrator\AppData\Local\Programs\Python\Python36\lib\site-packages\redis\connection.py", line 518, in connect
    sock = self._connect()
  File "C:\Users\Administrator\AppData\Local\Programs\Python\Python36\lib\site-packages\redis\connection.py", line 575, in _connect
    raise err
  File "C:\Users\Administrator\AppData\Local\Programs\Python\Python36\lib\site-packages\redis\connection.py", line 563, in _connect
    sock.connect(socket_address)
TimeoutError: [WinError 10060] 由于连接方在一段时间后没有正确答复或连接的主机没有反应，连接尝试失败。

During handling of the above exception, another exception occurred:

Traceback (most recent call last):
  File "C:\Users\Administrator\AppData\Local\Programs\Python\Python36\lib\site-packages\flask\app.py", line 2446, in wsgi_app
    response = self.full_dispatch_request()
  File "C:\Users\Administrator\AppData\Local\Programs\Python\Python36\lib\site-packages\flask\app.py", line 1951, in full_dispatch_request
    rv = self.handle_user_exception(e)
  File "C:\Users\Administrator\AppData\Local\Programs\Python\Python36\lib\site-packages\flask\app.py", line 1820, in handle_user_exception
    reraise(exc_type, exc_value, tb)
  File "C:\Users\Administrator\AppData\Local\Programs\Python\Python36\lib\site-packages\flask\_compat.py", line 39, in reraise
    raise value
  File "C:\Users\Administrator\AppData\Local\Programs\Python\Python36\lib\site-packages\flask\app.py", line 1949, in full_dispatch_request
    rv = self.dispatch_request()
  File "C:\Users\Administrator\AppData\Local\Programs\Python\Python36\lib\site-packages\flask\app.py", line 1935, in dispatch_request
    return self.view_functions[rule.endpoint](**req.view_args)
  File "c:\Users\Administrator\Desktop\CookiesPool-master\cookiespool\api.py", line 78, in count
    count = getattr(g, website + '_cookies').count()
  File "c:\Users\Administrator\Desktop\CookiesPool-master\cookiespool\db.py", line 55, in count
    return self.db.hlen(self.name())
  File "C:\Users\Administrator\AppData\Local\Programs\Python\Python36\lib\site-packages\redis\client.py", line 2735, in hlen
    return self.execute_command('HLEN', name)
  File "C:\Users\Administrator\AppData\Local\Programs\Python\Python36\lib\site-packages\redis\client.py", line 836, in execute_command
    conn = self.connection or pool.get_connection(command_name, **options)
  File "C:\Users\Administrator\AppData\Local\Programs\Python\Python36\lib\site-packages\redis\connection.py", line 1051, in get_connection
    connection.connect()
  File "C:\Users\Administrator\AppData\Local\Programs\Python\Python36\lib\site-packages\redis\connection.py", line 523, in connect
    raise ConnectionError(self._error_message(e))
redis.exceptions.ConnectionError: Error 10060 connecting to 47.106.107.0:6379. 由于连接方在一段时间后没有正确答复或连接的主机没有反应，连接尝试失败。.
2019-11-06 09:25:20 _internal.py[line:122] INFO 127.0.0.1 - - [06/Nov/2019 09:25:20] "GET /newrank/count HTTP/1.1" 500 -
2019-11-06 09:26:21 _internal.py[line:122] INFO 127.0.0.1 - - [06/Nov/2019 09:26:21] "GET / HTTP/1.1" 200 -
2019-11-06 09:26:22 app.py[line:1891] ERROR Exception on /newrank/count [GET]
Traceback (most recent call last):
  File "C:\Users\Administrator\AppData\Local\Programs\Python\Python36\lib\site-packages\redis\connection.py", line 518, in connect
    sock = self._connect()
  File "C:\Users\Administrator\AppData\Local\Programs\Python\Python36\lib\site-packages\redis\connection.py", line 575, in _connect
    raise err
  File "C:\Users\Administrator\AppData\Local\Programs\Python\Python36\lib\site-packages\redis\connection.py", line 563, in _connect
    sock.connect(socket_address)
TimeoutError: [WinError 10060] 由于连接方在一段时间后没有正确答复或连接的主机没有反应，连接尝试失败。

During handling of the above exception, another exception occurred:

Traceback (most recent call last):
  File "C:\Users\Administrator\AppData\Local\Programs\Python\Python36\lib\site-packages\flask\app.py", line 2446, in wsgi_app
    response = self.full_dispatch_request()
  File "C:\Users\Administrator\AppData\Local\Programs\Python\Python36\lib\site-packages\flask\app.py", line 1951, in full_dispatch_request
    rv = self.handle_user_exception(e)
  File "C:\Users\Administrator\AppData\Local\Programs\Python\Python36\lib\site-packages\flask\app.py", line 1820, in handle_user_exception
    reraise(exc_type, exc_value, tb)
  File "C:\Users\Administrator\AppData\Local\Programs\Python\Python36\lib\site-packages\flask\_compat.py", line 39, in reraise
    raise value
  File "C:\Users\Administrator\AppData\Local\Programs\Python\Python36\lib\site-packages\flask\app.py", line 1949, in full_dispatch_request
    rv = self.dispatch_request()
  File "C:\Users\Administrator\AppData\Local\Programs\Python\Python36\lib\site-packages\flask\app.py", line 1935, in dispatch_request
    return self.view_functions[rule.endpoint](**req.view_args)
  File "c:\Users\Administrator\Desktop\CookiesPool-master\cookiespool\api.py", line 78, in count
    count = getattr(g, website + '_cookies').count()
  File "c:\Users\Administrator\Desktop\CookiesPool-master\cookiespool\db.py", line 55, in count
    return self.db.hlen(self.name())
  File "C:\Users\Administrator\AppData\Local\Programs\Python\Python36\lib\site-packages\redis\client.py", line 2735, in hlen
    return self.execute_command('HLEN', name)
  File "C:\Users\Administrator\AppData\Local\Programs\Python\Python36\lib\site-packages\redis\client.py", line 836, in execute_command
    conn = self.connection or pool.get_connection(command_name, **options)
  File "C:\Users\Administrator\AppData\Local\Programs\Python\Python36\lib\site-packages\redis\connection.py", line 1051, in get_connection
    connection.connect()
  File "C:\Users\Administrator\AppData\Local\Programs\Python\Python36\lib\site-packages\redis\connection.py", line 523, in connect
    raise ConnectionError(self._error_message(e))
redis.exceptions.ConnectionError: Error 10060 connecting to 47.106.107.0:6379. 由于连接方在一段时间后没有正确答复或连接的主机没有反应，连接尝试失败。.
2019-11-06 09:26:22 _internal.py[line:122] INFO 127.0.0.1 - - [06/Nov/2019 09:26:22] "GET /newrank/count HTTP/1.1" 500 -
2019-11-06 09:39:28 _internal.py[line:122] INFO  * Running on http://0.0.0.0:6000/ (Press CTRL+C to quit)
2019-11-06 09:40:18 _internal.py[line:122] INFO  * Running on http://0.0.0.0:5000/ (Press CTRL+C to quit)
2019-11-06 09:40:22 _internal.py[line:122] INFO 127.0.0.1 - - [06/Nov/2019 09:40:22] "GET / HTTP/1.1" 200 -
2019-11-06 09:50:45 _internal.py[line:122] INFO  * Running on http://0.0.0.0:5000/ (Press CTRL+C to quit)
2019-11-06 09:50:50 _internal.py[line:122] INFO 127.0.0.1 - - [06/Nov/2019 09:50:50] "GET / HTTP/1.1" 200 -
2019-11-06 09:52:03 _internal.py[line:122] INFO 127.0.0.1 - - [06/Nov/2019 09:52:03] "GET / HTTP/1.1" 200 -
2019-11-06 09:52:08 _internal.py[line:122] INFO 127.0.0.1 - - [06/Nov/2019 09:52:08] "GET /newrank/count HTTP/1.1" 200 -
2019-11-06 09:52:48 _internal.py[line:122] INFO  * Restarting with stat
2019-11-06 09:52:50 _internal.py[line:122] WARNING  * Debugger is active!
2019-11-06 09:52:50 _internal.py[line:122] INFO  * Debugger PIN: 274-836-947
2019-11-06 09:52:50 _internal.py[line:122] INFO  * Running on http://0.0.0.0:6000/ (Press CTRL+C to quit)
2019-11-06 09:56:44 _internal.py[line:122] INFO  * Restarting with stat
2019-11-06 09:56:46 _internal.py[line:122] WARNING  * Debugger is active!
2019-11-06 09:56:46 _internal.py[line:122] INFO  * Debugger PIN: 274-836-947
2019-11-06 09:56:47 _internal.py[line:122] INFO  * Running on http://0.0.0.0:6000/ (Press CTRL+C to quit)
2019-11-06 09:57:30 _internal.py[line:122] INFO  * Detected change in 'C:\\Users\\Administrator\\Desktop\\CookiesPool-master\\cookiespool\\config.py', reloading
2019-11-06 10:14:34 _internal.py[line:122] INFO  * Restarting with stat
2019-11-06 10:14:36 _internal.py[line:122] WARNING  * Debugger is active!
2019-11-06 10:14:36 _internal.py[line:122] INFO  * Debugger PIN: 274-836-947
2019-11-06 10:14:37 _internal.py[line:122] INFO  * Running on http://0.0.0.0:6000/ (Press CTRL+C to quit)
2019-11-06 10:23:04 _internal.py[line:122] INFO  * Restarting with stat
2019-11-06 10:23:06 _internal.py[line:122] WARNING  * Debugger is active!
2019-11-06 10:23:06 _internal.py[line:122] INFO  * Debugger PIN: 274-836-947
2019-11-06 10:23:07 _internal.py[line:122] INFO  * Running on http://0.0.0.0:5000/ (Press CTRL+C to quit)
2019-11-06 11:01:42 _internal.py[line:122] INFO  * Restarting with stat
2019-11-06 11:01:45 _internal.py[line:122] WARNING  * Debugger is active!
2019-11-06 11:01:45 _internal.py[line:122] INFO  * Debugger PIN: 274-836-947
2019-11-06 11:01:45 _internal.py[line:122] INFO  * Running on http://0.0.0.0:6000/ (Press CTRL+C to quit)
2019-11-06 11:03:31 _internal.py[line:122] INFO  * Restarting with stat
2019-11-06 11:03:33 _internal.py[line:122] WARNING  * Debugger is active!
2019-11-06 11:03:33 _internal.py[line:122] INFO  * Debugger PIN: 274-836-947
2019-11-06 11:03:34 _internal.py[line:122] INFO  * Running on http://0.0.0.0:6000/ (Press CTRL+C to quit)
2019-11-06 11:06:38 _internal.py[line:122] INFO  * Restarting with stat
2019-11-06 11:06:40 _internal.py[line:122] WARNING  * Debugger is active!
2019-11-06 11:06:40 _internal.py[line:122] INFO  * Debugger PIN: 274-836-947
2019-11-06 11:06:41 _internal.py[line:122] INFO  * Running on http://0.0.0.0:6000/ (Press CTRL+C to quit)
2019-11-06 11:08:29 _internal.py[line:122] INFO  * Restarting with stat
2019-11-06 11:08:31 _internal.py[line:122] WARNING  * Debugger is active!
2019-11-06 11:08:31 _internal.py[line:122] INFO  * Debugger PIN: 274-836-947
2019-11-06 11:08:32 _internal.py[line:122] INFO  * Running on http://0.0.0.0:6000/ (Press CTRL+C to quit)
2019-11-06 13:33:23 _internal.py[line:122] INFO  * Restarting with stat
2019-11-06 13:33:25 _internal.py[line:122] WARNING  * Debugger is active!
2019-11-06 13:33:25 _internal.py[line:122] INFO  * Debugger PIN: 274-836-947
2019-11-06 13:33:26 _internal.py[line:122] INFO  * Running on http://0.0.0.0:6000/ (Press CTRL+C to quit)
2019-11-06 13:33:39 _internal.py[line:122] INFO  * Detected change in 'C:\\Users\\Administrator\\Desktop\\CookiesPool-master\\cookiespool\\config.py', reloading
2019-11-06 13:33:51 _internal.py[line:122] INFO  * Restarting with stat
2019-11-06 13:33:53 _internal.py[line:122] WARNING  * Debugger is active!
2019-11-06 13:33:53 _internal.py[line:122] INFO  * Debugger PIN: 274-836-947
2019-11-06 13:33:53 _internal.py[line:122] INFO  * Running on http://0.0.0.0:8888/ (Press CTRL+C to quit)
2019-11-06 13:33:55 _internal.py[line:122] INFO 127.0.0.1 - - [06/Nov/2019 13:33:55] "GET /newrank/count HTTP/1.1" 200 -
2019-11-06 13:46:25 _internal.py[line:122] INFO  * Restarting with stat
2019-11-06 13:46:26 _internal.py[line:122] WARNING  * Debugger is active!
2019-11-06 13:46:26 _internal.py[line:122] INFO  * Debugger PIN: 274-836-947
2019-11-06 13:46:27 _internal.py[line:122] INFO  * Running on http://0.0.0.0:8888/ (Press CTRL+C to quit)
2019-11-06 13:46:34 _internal.py[line:122] INFO 127.0.0.1 - - [06/Nov/2019 13:46:34] "GET /newrank/count HTTP/1.1" 200 -
2019-11-06 13:47:15 _internal.py[line:122] INFO  * Detected change in 'C:\\Users\\Administrator\\Desktop\\CookiesPool-master\\cookiespool\\api.py', reloading
2019-11-06 13:58:08 _internal.py[line:122] INFO  * Restarting with stat
